Traceback (most recent call last):
  File "H:\pychram\pulled\newtest\vernew.py", line 43, in get_tags
    response = client.list_tags_for_resource(ResourceArn=resource_arn)
               ^^^^^^^^^^^^^^^^^^^^^^^^^^^^^
  File "C:\Users\F37YHCS\AppData\Roaming\Python\Python311\site-packages\botocore\client.py", line 918, in __getattr__
    raise AttributeError(
AttributeError: 'EC2' object has no attribute 'list_tags_for_resource'

During handling of the above exception, another exception occurred:

Traceback (most recent call last):
  File "H:\pychram\pulled\newtest\vernew.py", line 67, in <module>
    tags = get_tags(clients[region]['ec2'], 'ec2', instance['InstanceId'])
           ^^^^^^^^^^^^^^^^^^^^^^^^^^^^^^^^^^^^^^^^^^^^^^^^^^^^^^^^^^^^^^^
  File "H:\pychram\pulled\newtest\vernew.py", line 49, in get_tags
    except client.exceptions.ResourceNotFoundException:
           ^^^^^^^^^^^^^^^^^^^^^^^^^^^^^^^^^^^^^^^^^^^
  File "C:\Users\F37YHCS\AppData\Roaming\Python\Python311\site-packages\botocore\errorfactory.py", line 51, in __getattr__
    raise AttributeError(
AttributeError: <botocore.errorfactory.EC2Exceptions object at 0x0000022E73FC9790> object has no attribute ResourceNotFoundException. Valid exceptions are:

F37YHCS@CPC-fnufa-TSIY7 MINGW64 /h/pychram/pulled/newtest
$ python vernew.py
Processing region: us-east-1
C:\Users\F37YHCS\AppData\Roaming\Python\Python311\site-packages\urllib3\connectionpool.py:1099: InsecureRequestWarning: Unverified HTTPS request is being made to host 'ec2.us-east-1.amazonaws.com'. Adding certificate verification is strongly advised. See: https://urllib3.readthedocs.io/en/latest/advanced-usage.html#tls-warnings
  warnings.warn(
Traceback (most recent call last):
  File "H:\pychram\pulled\newtest\vernew.py", line 43, in get_tags
    response = client.list_tags_for_resource(ResourceArn=resource_arn)
               ^^^^^^^^^^^^^^^^^^^^^^^^^^^^^
  File "C:\Users\F37YHCS\AppData\Roaming\Python\Python311\site-packages\botocore\client.py", line 918, in __getattr__
    raise AttributeError(
AttributeError: 'EC2' object has no attribute 'list_tags_for_resource'

During handling of the above exception, another exception occurred:

Traceback (most recent call last):
  File "H:\pychram\pulled\newtest\vernew.py", line 68, in <module>
    tags = get_tags(clients[region]['ec2'], 'ec2', instance_id)
           ^^^^^^^^^^^^^^^^^^^^^^^^^^^^^^^^^^^^^^^^^^^^^^^^^^^^
  File "H:\pychram\pulled\newtest\vernew.py", line 49, in get_tags
    except client.exceptions.NoSuchEntityException:
           ^^^^^^^^^^^^^^^^^^^^^^^^^^^^^^^^^^^^^^^
  File "C:\Users\F37YHCS\AppData\Roaming\Python\Python311\site-packages\botocore\errorfactory.py", line 51, in __getattr__
    raise AttributeError(
AttributeError: <botocore.errorfactory.EC2Exceptions object at 0x000001A73EB65C90> object has no attribute NoSuchEntityException. Valid exceptions are:
